Workbook

Sheet Final

Sheet Types of Product
B3: ITEM CODE | C3: PRODUCT CODE
B4: CBBA | C4: Cowbell Banana
B5: CBCF | C5: Cowbell Coffee
B6: CBMO | C6: Cowbell Mocha
B7: CBST | C7: Cowbell Strawberry
B8: MKCH | C8: Miksi Choco
B9: MKCF | C9: Miksi Coffee
B10: MKST | C10: Miksi Strawberry
B11: YUWH | C11: Yumvita Wheat
B12: YUMWH | C12: Yumvita Maize
B13: YURI | C13: Yumvita Rice
B14: NONE | C14: No Production

Sheet Jan
A2: Date | B2: Types of Product | C2: Type of Shift | D2: No. of Tonnes Produced
A3: 46023 | C3: Morning Shift
C4: Afternoon Shift
C5: Evening Shift
C6: Total Producted
A7: 46024 | C7: Morning Shift
C8: Afternoon Shift
C9: Evening Shift
C10: Total Producted
A11: 46025 | C11: Morning Shift
C12: Afternoon Shift
C13: Evening Shift
C14: Total Producted
A15: 46026 | C15: Morning Shift
C16: Afternoon Shift
C17: Evening Shift
C18: Total Producted
A19: 46027 | C19: Morning Shift
C20: Afternoon Shift
C21: Evening Shift
C22: Total Producted
A23: 46028 | C23: Morning Shift
C24: Afternoon Shift
C25: Evening Shift
C26: Total Producted
A27: 46029 | C27: Morning Shift
C28: Afternoon Shift
C29: Evening Shift
C30: Total Producted
A31: 46030 | C31: Morning Shift
C32: Afternoon Shift
C33: Evening Shift
C34: Total Producted
A35: 46031 | C35: Morning Shift
C36: Afternoon Shift
C37: Evening Shift
C38: Total Producted
A39: 46032 | C39: Morning Shift
C40: Afternoon Shift
C41: Evening Shift
...

Sheet Feb
A2: Date | B2: Types of Product | C2: Type of Shift | D2: No. of Tonnes Produced
A3: 46054 | C3: Morning Shift
C4: Afternoon Shift
C5: Evening Shift
C6: Total Producted
A7: 46055 | C7: Morning Shift
C8: Afternoon Shift
C9: Evening Shift
C10: Total Producted
A11: 46056 | C11: Morning Shift
C12: Afternoon Shift
C13: Evening Shift
C14: Total Producted
A15: 46057 | C15: Morning Shift
C16: Afternoon Shift
C17: Evening Shift
C18: Total Producted
A19: 46058 | C19: Morning Shift
C20: Afternoon Shift
C21: Evening Shift
C22: Total Producted
A23: 46059 | C23: Morning Shift
C24: Afternoon Shift
C25: Evening Shift
C26: Total Producted
A27: 46060 | C27: Morning Shift
C28: Afternoon Shift
C29: Evening Shift
C30: Total Producted
A31: 46061 | C31: Morning Shift
C32: Afternoon Shift
C33: Evening Shift
C34: Total Producted
A35: 46062 | C35: Morning Shift
C36: Afternoon Shift
C37: Evening Shift
C38: Total Producted
A39: 46063 | C39: Morning Shift
C40: Afternoon Shift
C41: Evening Shift
...

Sheet Mar
A2: Date | B2: Types of Product | C2: Type of Shift | D2: No. of Tonnes Produced
A3: 46054 | C3: Morning Shift
C4: Afternoon Shift
C5: Evening Shift
C6: Total Producted
A7: 46055 | C7: Morning Shift
C8: Afternoon Shift
C9: Evening Shift
C10: Total Producted
A11: 46056 | C11: Morning Shift
C12: Afternoon Shift
C13: Evening Shift
C14: Total Producted
A15: 46057 | C15: Morning Shift
C16: Afternoon Shift
C17: Evening Shift
C18: Total Producted
A19: 46058 | C19: Morning Shift
C20: Afternoon Shift
C21: Evening Shift
C22: Total Producted
A23: 46059 | C23: Morning Shift
C24: Afternoon Shift
C25: Evening Shift
C26: Total Producted
A27: 46060 | C27: Morning Shift
C28: Afternoon Shift
C29: Evening Shift
C30: Total Producted
A31: 46061 | C31: Morning Shift
C32: Afternoon Shift
C33: Evening Shift
C34: Total Producted
A35: 46062 | C35: Morning Shift
C36: Afternoon Shift
C37: Evening Shift
C38: Total Producted
A39: 46063 | C39: Morning Shift
C40: Afternoon Shift
C41: Evening Shift
...

Sheet Apr
A2: Date | B2: Types of Product | C2: Type of Shift | D2: No. of Tonnes Produced
A3: 46054 | C3: Morning Shift
C4: Afternoon Shift
C5: Evening Shift
C6: Total Producted
A7: 46055 | C7: Morning Shift
C8: Afternoon Shift
C9: Evening Shift
C10: Total Producted
A11: 46056 | C11: Morning Shift
C12: Afternoon Shift
C13: Evening Shift
C14: Total Producted
A15: 46057 | C15: Morning Shift
C16: Afternoon Shift
C17: Evening Shift
C18: Total Producted
A19: 46058 | C19: Morning Shift
C20: Afternoon Shift
C21: Evening Shift
C22: Total Producted
A23: 46059 | C23: Morning Shift
C24: Afternoon Shift
C25: Evening Shift
C26: Total Producted
A27: 46060 | C27: Morning Shift
C28: Afternoon Shift
C29: Evening Shift
C30: Total Producted
A31: 46061 | C31: Morning Shift
C32: Afternoon Shift
C33: Evening Shift
C34: Total Producted
A35: 46062 | C35: Morning Shift
C36: Afternoon Shift
C37: Evening Shift
C38: Total Producted
A39: 46063 | C39: Morning Shift
C40: Afternoon Shift
C41: Evening Shift
...

Sheet May
A2: Date | B2: Types of Product | C2: Type of Shift | D2: No. of Tonnes Produced
A3: 46054 | C3: Morning Shift
C4: Afternoon Shift
C5: Evening Shift
C6: Total Producted
A7: 46055 | C7: Morning Shift
C8: Afternoon Shift
C9: Evening Shift
C10: Total Producted
A11: 46056 | C11: Morning Shift
C12: Afternoon Shift
C13: Evening Shift
C14: Total Producted
A15: 46057 | C15: Morning Shift
C16: Afternoon Shift
C17: Evening Shift
C18: Total Producted
A19: 46058 | C19: Morning Shift
C20: Afternoon Shift
C21: Evening Shift
C22: Total Producted
A23: 46059 | C23: Morning Shift
C24: Afternoon Shift
C25: Evening Shift
C26: Total Producted
A27: 46060 | C27: Morning Shift
C28: Afternoon Shift
C29: Evening Shift
C30: Total Producted
A31: 46061 | C31: Morning Shift
C32: Afternoon Shift
C33: Evening Shift
C34: Total Producted
A35: 46062 | C35: Morning Shift
C36: Afternoon Shift
C37: Evening Shift
C38: Total Producted
A39: 46063 | C39: Morning Shift
C40: Afternoon Shift
C41: Evening Shift
...

Sheet June
A2: Date | B2: Types of Product | C2: Type of Shift | D2: No. of Tonnes Produced
A3: 46054 | C3: Morning Shift
C4: Afternoon Shift
C5: Evening Shift
C6: Total Producted
A7: 46055 | C7: Morning Shift
C8: Afternoon Shift
C9: Evening Shift
C10: Total Producted
A11: 46056 | C11: Morning Shift
C12: Afternoon Shift
C13: Evening Shift
C14: Total Producted
A15: 46057 | C15: Morning Shift
C16: Afternoon Shift
C17: Evening Shift
C18: Total Producted
A19: 46058 | C19: Morning Shift
C20: Afternoon Shift
C21: Evening Shift
C22: Total Producted
A23: 46059 | C23: Morning Shift
C24: Afternoon Shift
C25: Evening Shift
C26: Total Producted
A27: 46060 | C27: Morning Shift
C28: Afternoon Shift
C29: Evening Shift
C30: Total Producted
A31: 46061 | C31: Morning Shift
C32: Afternoon Shift
C33: Evening Shift
C34: Total Producted
A35: 46062 | C35: Morning Shift
C36: Afternoon Shift
C37: Evening Shift
C38: Total Producted
A39: 46063 | C39: Morning Shift
C40: Afternoon Shift
C41: Evening Shift
...

Sheet July
A2: Date | B2: Types of Product | C2: Type of Shift | D2: No. of Tonnes Produced
A3: 46054 | C3: Morning Shift
C4: Afternoon Shift
C5: Evening Shift
C6: Total Producted
A7: 46055 | C7: Morning Shift
C8: Afternoon Shift
C9: Evening Shift
C10: Total Producted
A11: 46056 | C11: Morning Shift
C12: Afternoon Shift
C13: Evening Shift
C14: Total Producted
A15: 46057 | C15: Morning Shift
C16: Afternoon Shift
C17: Evening Shift
C18: Total Producted
A19: 46058 | C19: Morning Shift
C20: Afternoon Shift
C21: Evening Shift
C22: Total Producted
A23: 46059 | C23: Morning Shift
C24: Afternoon Shift
C25: Evening Shift
C26: Total Producted
A27: 46060 | C27: Morning Shift
C28: Afternoon Shift
C29: Evening Shift
C30: Total Producted
A31: 46061 | C31: Morning Shift
C32: Afternoon Shift
C33: Evening Shift
C34: Total Producted
A35: 46062 | C35: Morning Shift
C36: Afternoon Shift
C37: Evening Shift
C38: Total Producted
A39: 46063 | C39: Morning Shift
C40: Afternoon Shift
C41: Evening Shift
...

Sheet Aug
A2: Date | B2: Types of Product | C2: Type of Shift | D2: No. of Tonnes Produced
A3: 46054 | C3: Morning Shift
C4: Afternoon Shift
C5: Evening Shift
C6: Total Producted
A7: 46055 | C7: Morning Shift
C8: Afternoon Shift
C9: Evening Shift
C10: Total Producted
A11: 46056 | C11: Morning Shift
C12: Afternoon Shift
C13: Evening Shift
C14: Total Producted
A15: 46057 | C15: Morning Shift
C16: Afternoon Shift
C17: Evening Shift
C18: Total Producted
A19: 46058 | C19: Morning Shift
C20: Afternoon Shift
C21: Evening Shift
C22: Total Producted
A23: 46059 | C23: Morning Shift
C24: Afternoon Shift
C25: Evening Shift
C26: Total Producted
A27: 46060 | C27: Morning Shift
C28: Afternoon Shift
C29: Evening Shift
C30: Total Producted
A31: 46061 | C31: Morning Shift
C32: Afternoon Shift
C33: Evening Shift
C34: Total Producted
A35: 46062 | C35: Morning Shift
C36: Afternoon Shift
C37: Evening Shift
C38: Total Producted
A39: 46063 | C39: Morning Shift
C40: Afternoon Shift
C41: Evening Shift
...

Sheet Sept
A1: Date | B1: Product Code | C1: Product Name | D1: Type of Shift | E1: No. of Tonnes Produced
A2: 46266 | B2: NONE | C2: =IF(B2<>"",_xlfn.XLOOKUP(B2,'Types of Product'!$B$4:$B$14,'Types of Product'!$C$4:$C$14,"No Production"),"") -> No Production | D2: Morning Shift | E2: 0
B3: NONE | C3: =IF(B3<>"",_xlfn.XLOOKUP(B3,'Types of Product'!$B$4:$B$14,'Types of Product'!$C$4:$C$14,"No Production"),"") -> No Production | D3: Afternoon Shift | E3: 0
B4: NONE | C4: =IF(B4<>"",_xlfn.XLOOKUP(B4,'Types of Product'!$B$4:$B$14,'Types of Product'!$C$4:$C$14,"No Production"),"") -> No Production | D4: Evening Shift | E4: 0
A5: 46267 | B5: NONE | C5: =IF(B5<>"",_xlfn.XLOOKUP(B5,'Types of Product'!$B$4:$B$14,'Types of Product'!$C$4:$C$14,"No Production"),"") -> No Production | D5: Morning Shift | E5: 0
B6: MKCH | C6: =IF(B6<>"",_xlfn.XLOOKUP(B6,'Types of Product'!$B$4:$B$14,'Types of Product'!$C$4:$C$14,"No Production"),"") -> Miksi Choco | D6: Afternoon Shift | E6: 12
B7: MKCH | C7: =IF(B7<>"",_xlfn.XLOOKUP(B7,'Types of Product'!$B$4:$B$14,'Types of Product'!$C$4:$C$14,"No Production"),"") -> Miksi Choco | D7: Evening Shift | E7: 20
B8: CBCF | C8: =IF(B8<>"",_xlfn.XLOOKUP(B8,'Types of Product'!$B$4:$B$14,'Types of Product'!$C$4:$C$14,"No Production"),"") -> Cowbell Coffee | D8: Evening Shift | E8: 20
A9: 46268 | B9: CBCF | C9: =IF(B9<>"",_xlfn.XLOOKUP(B9,'Types of Product'!$B$4:$B$14,'Types of Product'!$C$4:$C$14,"No Production"),"") -> Cowbell Coffee | D9: Morning Shift | E9: 30
B10: CBCF | C10: =IF(B10<>"",_xlfn.XLOOKUP(B10,'Types of Product'!$B$4:$B$14,'Types of Product'!$C$4:$C$14,"No Production"),"") -> Cowbell Coffee | D10: Afternoon Shift | E10: 32
B11: CBCF | C11: =IF(B11<>"",_xlfn.XLOOKUP(B11,'Types of Product'!$B$4:$B$14,'Types of Product'!$C$4:$C$14,"No Production"),"") -> Cowbell Coffee | D11: Evening Shift | E11: 30
A12: 46269 | B12: MKCH | C12: =IF(B12<>"",_xlfn.XLOOKUP(B12,'Types of Product'!$B$4:$B$14,'Types of Product'!$C$4:$C$14,"No Production"),"") -> Miksi Choco
C13: =IF(B13<>"",_xlfn.XLOOKUP(B13,'Types of Product'!$B$4:$B$14,'Types of Product'!$C$4:$C$14,"No Production"),"")
C14: =IF(B14<>"",_xlfn.XLOOKUP(B14,'Types of Product'!$B$4:$B$14,'Types of Product'!$C$4:$C$14,"No Production"),"")
C15: =IF(B15<>"",_xlfn.XLOOKUP(B15,'Types of Product'!$B$4:$B$14,'Types of Product'!$C$4:$C$14,"No Production"),"")
C16: =IF(B16<>"",_xlfn.XLOOKUP(B16,'Types of Product'!$B$4:$B$14,'Types of Product'!$C$4:$C$14,"No Production"),"")
C17: =IF(B17<>"",_xlfn.XLOOKUP(B17,'Types of Product'!$B$4:$B$14,'Types of Product'!$C$4:$C$14,"No Production"),"")
C18: =IF(B18<>"",_xlfn.XLOOKUP(B18,'Types of Product'!$B$4:$B$14,'Types of Product'!$C$4:$C$14,"No Production"),"")
C19: =IF(B19<>"",_xlfn.XLOOKUP(B19,'Types of Product'!$B$4:$B$14,'Types of Product'!$C$4:$C$14,"No Production"),"")
C20: =IF(B20<>"",_xlfn.XLOOKUP(B20,'Types of Product'!$B$4:$B$14,'Types of Product'!$C$4:$C$14,"No Production"),"")
C21: =IF(B21<>"",_xlfn.XLOOKUP(B21,'Types of Product'!$B$4:$B$14,'Types of Product'!$C$4:$C$14,"No Production"),"")
C22: =IF(B22<>"",_xlfn.XLOOKUP(B22,'Types of Product'!$B$4:$B$14,'Types of Product'!$C$4:$C$14,"No Production"),"")
C23: =IF(B23<>"",_xlfn.XLOOKUP(B23,'Types of Product'!$B$4:$B$14,'Types of Product'!$C$4:$C$14,"No Production"),"")
C24: =IF(B24<>"",_xlfn.XLOOKUP(B24,'Types of Product'!$B$4:$B$14,'Types of Product'!$C$4:$C$14,"No Production"),"")
... C162: =IF(B162<>"",_xlfn.XLOOKUP(B162,'Types of Product'!$B$4:$B$14,'Types of Product'!$C$4:$C$14,"No Production"),"")
